Workbook

Sheet WBS
A1: Mã WBS | B1: Tên công việc / Hoạt động | C1: Sản phẩm bàn giao | D1: Phụ trách | E1: Bắt đầu | F1: Kết thúc
A2: 1 | B2: Quản lý dự án | C2: Hồ sơ quản lý dự án | D2: PM | E2: =MIN(E3,E7,E11,E14) -> 46195 | F2: =MAX(F3,F7,F11,F14) -> 46325
A3: 1.1 | B3: Khởi động dự án | C3: Project Charter, biên bản kick-off | D3: PM | E3: =MIN(E4,E5,E6) -> 46195 | F3: =MAX(F4,F5,F6) -> 46198
A4: 1.1.1 | B4: Lập Điều lệ dự án (Project Charter) | C4: Project Charter | D4: PM | E4: 46195 | F4: 46196
A5: 1.1.2 | B5: Lập ma trận RACI | C5: RACI | D5: PM | E5: 46196 | F5: 46196
A6: 1.1.3 | B6: Tổ chức họp khởi động (Kick-off) | C6: Biên bản kick-off | D6: PM | E6: 46198 | F6: 46198
A7: 1.2 | B7: Lập kế hoạch dự án | C7: WBS, Master Plan Master Schedule; Cost Baseline Quality Plan; Change Management Plan | D7: PM | E7: =MIN(E8,E9,E10) -> 46195 | F7: =MAX(F8,F9,F10) -> 46209
A8: 1.2.1 | B8: Lập WBS, Master Plan | C8: WBS, Master Plan | D8: PM | E8: 46195 | F8: 46203
A9: 1.2.2 | B9: Lập đường cơ sở tiến độ & chi phí | C9: Master Schedule; Cost Baseline | D9: PM | E9: 46199 | F9: 46209
A10: 1.2.3 | B10: Kế hoạch chất lượng & quản lý thay đổi | C10: Quality Plan; Change Management Plan | D10: PM | E10: 46204 | F10: 46209
A11: 1.3 | B11: Giám sát & kiểm soát (LOE) | C11: Báo cáo, quyết định kiểm soát | D11: PM | E11: =MIN(E12,E13) -> 46322 | F11: =MAX(F12,F13) -> 46325
A12: 1.3.1 | B12: Báo cáo tiến độ tuần & họp tiến độ | C12: Weekly Report | D12: PM | E12: 46322 | F12: 46325
A13: 1.3.2 | B13: Quản lý rủi ro & vấn đề | C13: Risk/Issue Log | D13: PM | E13: 46324 | F13: 46325
A14: 1.4 | B14: Kết thúc dự án | C14: Hồ sơ nghiệm thu, bài học kinh nghiệm, Báo cáo tổng kết dự án, Báo cáo đánh giá dự án | D14: PM | E14: =MIN(E15,E16) -> 46322 | F14: =MAX(F15,F16) -> 46325
A15: 1.4.1 | B15: Nghiệm thu tổng thể & bàn giao hồ sơ | C15: Biên bản nghiệm thu tổng thể, Báo cáo đánh giá dự án | D15: PM | E15: 46322 | F15: 46325
A16: 1.4.2 | B16: Bài học kinh nghiệm & đóng hồ sơ dự án | C16: Báo cáo bài học kinh nghiệm, Báo cáo tổng kết dự án | D16: PM | E16: 46324 | F16: 46325
A17: 2 | B17: Phân tích hệ thống (System Analysis) | C17: SRS | D17: BA | E17: =MIN(E18,E22,E27,E28,E29) -> 46195 | F17: =MAX(F18,F22,F27,F28,F29) -> 46213
A18: 2.1 | B18: Khảo sát hiện trạng (AS-IS) | C18: Báo cáo khảo sát hiện trạng | D18: BA | E18: =MIN(E19,E20,E21) -> 46195 | F18: =MAX(F19,F20,F21) -> 46204
A19: 2.1.1 | B19: Họp phân tích yêu cầu với nghiệp vụ và các bên liên quan | C19: Biên bản workshop | D19: BA | E19: 46195 | F19: 46198
A20: 2.1.2 | B20: Khảo sát hệ thống | C20: Báo cáo khảo sát hệ thống cũ | D20: BA | E20: 46196 | F20: 46199
A21: 2.1.3 | B21: Lập báo cáo hiện trạng (AS-IS) | C21: Báo cáo AS-IS | D21: BA | E21: 46203 | F21: 46204
A22: 2.2 | B22: Đặc tả yêu cầu chức năng (SRS) | C22: SRS – Specification | D22: BA | E22: =MIN(E23,E24,E25,E26,E27,E28,E29) -> 46199 | F22: =MAX(F23,F24,F25,F26,F27,F28,F29) -> 46213
A23: 2.2.1 | B23: SRS – Quản lý sản phẩm (tìm kiếm, danh mục, chi tiết, tồn kho) | C23: SRS Quản lý sản phẩm | D23: BA | E23: 46199 | F23: 46206
A24: 2.2.2 | B24: SRS – Quản lý đơn hàng (giỏ hàng, đặt hàng, thanh toán, hủy đơn) | C24: SRS Quản lý đơn hàng | D24: BA | E24: 46203 | F24: 46211
A25: 2.2.3 | B25: SRS – Quản lý khách hàng (đăng ký, đăng nhập, hồ sơ, dữ liệu cá nhân) | C25: SRS Quản lý khách hàng | D25: BA | E25: 46199 | F25: 46206
A26: 2.2.5 | B26: SRS – Tích hợp hệ thống (Main System, chi nhánh, vận chuyển) | C26: SRS Tích hợp | D26: BA | E26: 46205 | F26: 46212
A27: 2.3 | B27: Đặc tả yêu cầu phi chức năng (24/7, ≤ 2 giây, bảo mật, dữ liệu cá nhân) | C27: NFR Specification | D27: SA | E27: 46205 | F27: 46210
A28: 2.4 | B28: Thiết kế quy trình nghiệp vụ | C28: SRS Quy trình nghiệp vụ | D28: BA | E28: 46205 | F28: 46212
A29: 46144 | B29: Rà soát & phê duyệt SRS | C29: SRS được ký duyệt | D29: PM | E29: 46213 | F29: 46213
A30: 3 | B30: Thiết kế hệ thống | C30: Tài liệu thiết kế hệ thống SDD | D30: SA | E30: =MIN(E31,E36,E39,E46,E50,E55) -> 46206 | F30: =MAX(F31,F36,F39,F46,F50,F55) -> 46234
A31: 3.1 | B31: Thiết kế kiến trúc & hạ tầng (HLD) | C31: Tài liệu kiến trúc hệ thống | D31: SA | E31: =MIN(E32,E33,E34,E35) -> 46210 | F31: =MAX(F32,F33,F34,F35) -> 46219
A32: 3.1.1 | B32: Thiết kế kiến trúc ứng dụng & phương án sẵn sàng 24/7 | C32: Sơ đồ kiến trúc, phương án HA | D32: SA | E32: 46210 | F32: 46213
A33: 3.1.2 | B33: Tính toán quy mô hạ tầng & phương án mở rộng | C33: Sizing & scaling plan | D33: SA | E33: 46217 | F33: 46219
A34: 3.1.3 | B34: Thiết kế an toàn thông tin & bảo vệ dữ liệu cá nhân | C34: Security Design | D34: SA | E34: 46213 | F34: 46218
A35: 3.1.4 | B35: Thiết kế giám sát, sao lưu & phục hồi | C35: Monitoring & Backup Design | D35: OPS | E35: 46217 | F35: 46219
A36: 3.2 | B36: Thiết kế cơ sở dữ liệu | C36: Data Model Design, Data Dictionary | D36: SA | E36: =MIN(E37,E38) -> 46212 | F36: =MAX(F37,F38) -> 46223
A37: 3.2.1 | B37: Mô hình dữ liệu logic & vật lý (ERD) | C37: ERD | D37: SA | E37: 46212 | F37: 46217
A38: 3.2.2 | B38: Từ điển dữ liệu, chỉ mục & phân quyền truy cập | C38: Data Dictionary | D38: DEV | E38: 46218 | F38: 46223
A39: 3.3 | B39: Thiết kế UI/UX | C39: Menu Layer, wireframe, mockup | D39: UX | E39: =MIN(E40,E41,E42,E43,E44,E45) -> 46206 | F39: =MAX(F40,F41,F42,F43,F44,F45) -> 46224
A40: 3.3.1 | B40: Sơ đồ trang & Menu Layer | C40: Menu Layer / Sitemap | D40: UX | E40: 46206 | F40: 46209
...

Sheet Gantt
A1: BIỂU ĐỒ GANTT THEO TUẦN (liên kết sheet WBS)
A2: Thanh tự vẽ theo ngày trong sheet WBS. Xanh đậm = giai đoạn (cấp 1), xanh nhạt = công việc. Cột cam = tuần Cut-over 01/07. Dùng +/− để thu gọn theo cấp.
A4: Mã WBS | B4: Tên công việc | C4: Bắt đầu | D4: Kết thúc | E4: Phụ trách | F4: 46461 | G4: 46468 | H4: 46475 | I4: 46482 | J4: 46489 | K4: 46496 | L4: 46503 | M4: 46510 | N4: 46517 | O4: 46524 | P4: 46531 | Q4: 46538 | R4: 46545 | S4: 46552 | T4: 46559 | U4: 46566 | V4: 46573 | W4: 46580 | X4: 46587 | Y4: 46594 | Z4: 46601
A5: =WBS!A2 -> 1 | B5: =WBS!B2 -> Quản lý dự án | C5: =WBS!E2 -> 46195 | D5: =WBS!F2 -> 46325 | E5: =WBS!D2 -> PM
A6: =WBS!A3 -> 1.1 | B6: =WBS!B3 -> Khởi động dự án | C6: =WBS!E3 -> 46195 | D6: =WBS!F3 -> 46198 | E6: =WBS!D3 -> PM
A7: =WBS!A4 -> 1.1.1 | B7: =WBS!B4 -> Lập Điều lệ dự án (Project Charter) | C7: =WBS!E4 -> 46195 | D7: =WBS!F4 -> 46196 | E7: =WBS!D4 -> PM
A8: =WBS!A5 -> 1.1.2 | B8: =WBS!B5 -> Lập ma trận RACI | C8: =WBS!E5 -> 46196 | D8: =WBS!F5 -> 46196 | E8: =WBS!D5 -> PM
A9: =WBS!A6 -> 1.1.3 | B9: =WBS!B6 -> Tổ chức họp khởi động (Kick-off) | C9: =WBS!E6 -> 46198 | D9: =WBS!F6 -> 46198 | E9: =WBS!D6 -> PM
A10: =WBS!A7 -> 1.2 | B10: =WBS!B7 -> Lập kế hoạch dự án | C10: =WBS!E7 -> 46195 | D10: =WBS!F7 -> 46209 | E10: =WBS!D7 -> PM
A11: =WBS!A8 -> 1.2.1 | B11: =WBS!B8 -> Lập WBS, Master Plan | C11: =WBS!E8 -> 46195 | D11: =WBS!F8 -> 46203 | E11: =WBS!D8 -> PM
A12: =WBS!A9 -> 1.2.2 | B12: =WBS!B9 -> Lập đường cơ sở tiến độ & chi phí | C12: =WBS!E9 -> 46199 | D12: =WBS!F9 -> 46209 | E12: =WBS!D9 -> PM
A13: =WBS!A10 -> 1.2.3 | B13: =WBS!B10 -> Kế hoạch chất lượng & quản lý thay đổi | C13: =WBS!E10 -> 46204 | D13: =WBS!F10 -> 46209 | E13: =WBS!D10 -> PM
A14: =WBS!A11 -> 1.3 | B14: =WBS!B11 -> Giám sát & kiểm soát (LOE) | C14: =WBS!E11 -> 46322 | D14: =WBS!F11 -> 46325 | E14: =WBS!D11 -> PM
A15: =WBS!A12 -> 1.3.1 | B15: =WBS!B12 -> Báo cáo tiến độ tuần & họp tiến độ | C15: =WBS!E12 -> 46322 | D15: =WBS!F12 -> 46325 | E15: =WBS!D12 -> PM
A16: =WBS!A13 -> 1.3.2 | B16: =WBS!B13 -> Quản lý rủi ro & vấn đề | C16: =WBS!E13 -> 46324 | D16: =WBS!F13 -> 46325 | E16: =WBS!D13 -> PM
... A23: =WBS!A20 -> 2.1.2 | B23: =WBS!B20 -> Khảo sát hệ thống | C23: =WBS!E20 -> 46196 | D23: =WBS!F20 -> 46199 | E23: =WBS!D20 -> BA
A24: =WBS!#REF! -> #ERROR! | B24: =WBS!#REF! -> #ERROR! | C24: =WBS!#REF! -> #ERROR! | D24: =WBS!#REF! -> #ERROR! | E24: =WBS!#REF! -> #ERROR!
A25: =WBS!A21 -> 2.1.3 | B25: =WBS!B21 -> Lập báo cáo hiện trạng (AS-IS) | C25: =WBS!E21 -> 46203 | D25: =WBS!F21 -> 46204 | E25: =WBS!D21 -> BA
A26: =WBS!A22 -> 2.2 | B26: =WBS!B22 -> Đặc tả yêu cầu chức năng (SRS) | C26: =WBS!E22 -> 46199 | D26: =WBS!F22 -> 46213 | E26: =WBS!D22 -> BA
A27: =WBS!A23 -> 2.2.1 | B27: =Gantt -> #NAME? | C27: =WBS!E23 -> 46199 | D27: =WBS!F23 -> 46206 | E27: =WBS!D23 -> BA
A28: =WBS!A24 -> 2.2.2 | B28: =WBS!B24 -> SRS – Quản lý đơn hàng (giỏ hàng, đặt hàng, thanh toán, hủy đơn) | C28: =WBS!E24 -> 46203 | D28: =WBS!F24 -> 46211 | E28: =WBS!D24 -> BA
A29: =WBS!A25 -> 2.2.3 | B29: =WBS!B25 -> SRS – Quản lý khách hàng (đăng ký, đăng nhập, hồ sơ, dữ liệu cá nhân) | C29: =WBS!E25 -> 46199 | D29: =WBS!F25 -> 46206 | E29: =WBS!D25 -> BA
A30: =#REF! -> #REF! | B30: =#REF! -> #REF! | C30: =#REF! -> #REF! | D30: =#REF! -> #REF! | E30: =#REF! -> #REF!
A31: =WBS!A26 -> 2.2.5 | B31: =WBS!B26 -> SRS – Tích hợp hệ thống (Main System, chi nhánh, vận chuyển) | C31: =WBS!E26 -> 46205 | D31: =WBS!F26 -> 46212 | E31: =WBS!D26 -> BA
A32: =WBS!A27 -> 2.3 | B32: =WBS!B27 -> Đặc tả yêu cầu phi chức năng (24/7, ≤ 2 giây, bảo mật, dữ liệu cá nhân) | C32: =WBS!E27 -> 46205 | D32: =WBS!F27 -> 46210 | E32: =WBS!D27 -> SA
A33: =WBS!A28 -> 2.4 | B33: =WBS!B28 -> Thiết kế quy trình nghiệp vụ | C33: =WBS!E28 -> 46205 | D33: =WBS!F28 -> 46212 | E33: =WBS!D28 -> BA
A34: =WBS!#REF! -> #ERROR! | B34: =WBS!#REF! -> #ERROR! | C34: =WBS!#REF! -> #ERROR! | D34: =WBS!#REF! -> #ERROR! | E34: =WBS!#REF! -> #ERROR!
A35: =WBS!A29 -> 46144 | B35: =WBS!B29 -> Rà soát & phê duyệt SRS | C35: =WBS!E29 -> 46213 | D35: =WBS!F29 -> 46213 | E35: =WBS!D29 -> PM
A36: =WBS!A30 -> 3 | B36: =WBS!B30 -> Thiết kế hệ thống | C36: =WBS!E30 -> 46206 | D36: =WBS!F30 -> 46234 | E36: =WBS!D30 -> SA
A37: =WBS!A31 -> 3.1 | B37: =WBS!B31 -> Thiết kế kiến trúc & hạ tầng (HLD) | C37: =WBS!E31 -> 46210 | D37: =WBS!F31 -> 46219 | E37: =WBS!D31 -> SA
A38: =WBS!A32 -> 3.1.1 | B38: =WBS!B32 -> Thiết kế kiến trúc ứng dụng & phương án sẵn sàng 24/7 | C38: =WBS!E32 -> 46210 | D38: =WBS!F32 -> 46213 | E38: =WBS!D32 -> SA
A39: =WBS!A33 -> 3.1.2 | B39: =WBS!B33 -> Tính toán quy mô hạ tầng & phương án mở rộng | C39: =WBS!E33 -> 46217 | D39: =WBS!F33 -> 46219 | E39: =WBS!D33 -> SA
A40: =WBS!A34 -> 3.1.3 | B40: =WBS!B34 -> Thiết kế an toàn thông tin & bảo vệ dữ liệu cá nhân | C40: =WBS!E34 -> 46213 | D40: =WBS!F34 -> 46218 | E40: =WBS!D34 -> SA
A41: =WBS!A35 -> 3.1.4 | B41: =WBS!B35 -> Thiết kế giám sát, sao lưu & phục hồi | C41: =WBS!E35 -> 46217 | D41: =WBS!F35 -> 46219 | E41: =WBS!D35 -> OPS
A42: =WBS!A36 -> 3.2 | B42: =WBS!B36 -> Thiết kế cơ sở dữ liệu | C42: =WBS!E36 -> 46212 | D42: =WBS!F36 -> 46223 | E42: =WBS!D36 -> SA
A43: =WBS!A37 -> 3.2.1 | B43: =WBS!B37 -> Mô hình dữ liệu logic & vật lý (ERD) | C43: =WBS!E37 -> 46212 | D43: =WBS!F37 -> 46217 | E43: =WBS!D37 -> SA
A44: =WBS!A38 -> 3.2.2 | B44: =WBS!B38 -> Từ điển dữ liệu, chỉ mục & phân quyền truy cập | C44: =WBS!E38 -> 46218 | D44: =WBS!F38 -> 46223 | E44: =WBS!D38 -> DEV
A45: =WBS!A39 -> 3.3 | B45: =WBS!B39 -> Thiết kế UI/UX | C45: =WBS!E39 -> 46206 | D45: =WBS!F39 -> 46224 | E45: =WBS!D39 -> UX
A46: =WBS!A40 -> 3.3.1 | B46: =WBS!B40 -> Sơ đồ trang & Menu Layer | C46: =WBS!E40 -> 46206 | D46: =WBS!F40 -> 46209 | E46: =WBS!D40 -> UX
... A55: =WBS!A49 -> 3.4.4 | B55: =WBS!B49 -> Đặc tả thiết kế API cho các phân hệ sản phẩm, đơn hàng, khách hàng | C55: =WBS!E49 -> 46218 | D55: =WBS!F49 -> 46224 | E55: =WBS!D49 -> SA
...
